<?xml version='1.0'?>
<sdf version='1.6'>
  <model name='my_drone'>
    <pose>0 0 0.087 0 0 0</pose>      <!-- 0 0 0.194923 0 0 0 -->
    <link name='base_link'>
      <velocity_decay>
        <linear>0.0</linear>
        <angular>0.0</angular>
      </velocity_decay>
      <inertial>
        <pose>0 0 0 0 0 0</pose>
        <mass>1.5</mass>   <!--1.5-->
        <inertia>
          <ixx>0.008</ixx>  
          <ixy>0</ixy>
          <ixz>0</ixz>
          <iyy>0.015</iyy>   
          <iyz>0</iyz>
          <izz>0.017</izz>   
        </inertia>
      </inertial>

      <sensor name="imu_sensor" type="imu">
        <pose>0 0 0 3.141593 0 0</pose>
        <always_on>1</always_on>
        <update_rate>1000.0</update_rate>
      </sensor>

      <collision name='base_link_collision'>
        <pose>0 0 -0.025 0 0 0</pose>    <!-- 0 0 -0.08 0 0 0 -->
        <geometry>
          <box>
            <size>0.385 0.385 0.125</size>   <!-- 0.47 0.47 0.23 -->
          </box>
        </geometry>
        <surface>
          <contact>
            <ode>
              <max_vel>100.0</max_vel>
              <min_depth>0.001</min_depth>
            </ode>
          </contact>
          <friction>
            <ode>
              <mu>1.0</mu>
              <mu2>1.0</mu2>
            </ode>
          </friction>
        </surface>
      </collision>
      <visual name='base_link_visual_0'> <!-- blocco grande in mezzo   tutte le seguenti pose sono fatte per ottenere 50 cm di diagonale e perpendicolarità tra le braccia del drone-->
        <pose>0 0 -0.005 0 1.570795 0</pose>
        <geometry>
          <box>
            <size>0.02 0.1 0.1</size>
          </box>
        </geometry>
        <material>
          <script>
            <name>Gazebo/FlatBlack</name>
            <uri>file://media/materials/scripts/gazebo.material</uri>
          </script>
        </material>
      </visual>
      <visual name='base_link_visual_1'>  <!-- blocco grande sotto-->
        <pose>0 0 -0.03 0 1.570795 0</pose>
        <geometry>
          <box>
            <size>0.04 0.1 0.1</size>
          </box>
        </geometry>
        <material>
          <script>
            <name>Gazebo/FlatBlack</name>
            <uri>file://media/materials/scripts/gazebo.material</uri>
          </script>
        </material>
      </visual>
      <visual name='base_link_visual_2'> <!-- blocco piccolo sopra-->
        <pose>0 0 -0.002 0 1.570795 0</pose>
        <geometry>
          <box>
            <size>0.07 0.07 0.08</size>
          </box>
        </geometry>
        <material>
          <script>
            <name>Gazebo/DarkGrey</name>
          </script>
        </material>
      </visual>
      <visual name='base_link_visual_3'>  <!-- braccia-->
        <pose>0 0 -0.005 0.7853975 1.570795 0</pose>
        <geometry>
          <box>
            <size>0.02 0.03 0.5</size>
          </box>
        </geometry>
        <material>
          <script>
            <name>Gazebo/FlatBlack</name>
            <uri>file://media/materials/scripts/gazebo.material</uri>
          </script>
        </material>
      </visual>
      <visual name='base_link_visual_4'>   <!-- braccia-->
        <pose>0 0 -0.005 -0.7853975 1.570795 0</pose>
        <geometry>
          <box>
            <size>0.02 0.03 0.5</size>
          </box>
        </geometry>
        <material>
          <script>
            <name>Gazebo/FlatBlack</name>
            <uri>file://media/materials/scripts/gazebo.material</uri>
          </script>
        </material>
      </visual>
      <visual name='base_link_visual_5'>   <!-- cilindri in fondo alle braccia-->
        <pose>0.176776695 0.176776695 -0.005 0 0 0</pose>   
        <geometry>
          <cylinder>
            <radius>0.015</radius>
            <length>0.02</length>
          </cylinder>
        </geometry>
        <material>
          <script>
            <name>Gazebo/FlatBlack</name>
            <uri>file://media/materials/scripts/gazebo.material</uri>
          </script>
        </material>
      </visual>
      <visual name='base_link_visual_6'>   <!-- cilindri in fondo alle braccia-->
        <pose>-0.176776695 0.176776695 -0.005 0 0 0</pose>   
        <geometry>
          <cylinder>
            <radius>0.015</radius>
            <length>0.02</length>
          </cylinder>
        </geometry>
        <material>
          <script>
            <name>Gazebo/FlatBlack</name>
            <uri>file://media/materials/scripts/gazebo.material</uri>
          </script>
        </material>
      </visual>
      <visual name='base_link_visual_7'>   <!-- cilindri in fondo alle braccia-->
        <pose>0.176776695 -0.176776695 -0.005 0 0 0</pose>   
        <geometry>
          <cylinder>
            <radius>0.015</radius>
            <length>0.02</length>
          </cylinder>
        </geometry>
        <material>
          <script>
            <name>Gazebo/FlatBlack</name>
            <uri>file://media/materials/scripts/gazebo.material</uri>
          </script>
        </material>
      </visual>
      <visual name='base_link_visual_8'>   <!-- cilindri in fondo alle braccia-->
        <pose>-0.176776695 -0.176776695 -0.005 0 0 0</pose>   
        <geometry>
          <cylinder>
            <radius>0.015</radius>
            <length>0.02</length>
          </cylinder>
        </geometry>
        <material>
          <script>
            <name>Gazebo/FlatBlack</name>
            <uri>file://media/materials/scripts/gazebo.material</uri>
          </script>
        </material>
      </visual>

      <!--visual name='base_link_visual'>
        <geometry>
          <mesh>
            <uri>model://iris_with_standoffs/meshes/iris.dae</uri>
          </mesh>
        </geometry>
        <material>
          <script>
            <name>Gazebo/DarkGrey</name>
          </script>
        </material>
      </visual-->

      <visual name='front_left_leg_visual_0'>
        <pose>0.176776695 0.176776695 -0.004 0 0 0</pose>  
        <geometry>
          <cylinder>
            <radius>0.005</radius>
            <length>0.045</length>
          </cylinder>
        </geometry>
        <material>
          <script>
            <name>Gazebo/FlatBlack</name>
            <uri>file://media/materials/scripts/gazebo.material</uri>
          </script>
        </material>
      </visual>
      <visual name='front_right_leg_visual_0'>
        <pose>0.176776695 -0.176776695 -0.004 0 0 0</pose>   
        <geometry>
          <cylinder>
            <radius>0.005</radius>
            <length>0.045</length>
          </cylinder>
        </geometry>
        <material>
          <script>
            <name>Gazebo/FlatBlack</name>
            <uri>file://media/materials/scripts/gazebo.material</uri>
          </script>
        </material>
      </visual>
      <visual name='rear_left_leg_visual_0'>
        <pose>-0.176776695 0.176776695 -0.004 0 0 0</pose>     
        <geometry>
          <cylinder>
            <radius>0.005</radius>
            <length>0.045</length>
          </cylinder>
        </geometry>
        <material>
          <script>
            <name>Gazebo/FlatBlack</name>
            <uri>file://media/materials/scripts/gazebo.material</uri>
          </script>
        </material>
      </visual>
      <visual name='rear_right_leg_visual_0'>
        <pose>-0.176776695 -0.176776695 -0.004 0 0 0</pose>    
        <geometry>
          <cylinder>
            <radius>0.005</radius>
            <length>0.045</length>
          </cylinder>
        </geometry>
        <material>
          <script>
            <name>Gazebo/FlatBlack</name>
            <uri>file://media/materials/scripts/gazebo.material</uri>
          </script>
        </material>
      </visual>
      <visual name='front_left_leg_visual_1'>
        <pose>0.176776695 0.176776695 -0.05 0 0 0</pose>  <!-- 0.123 0.22 -0.11 0 0 0 --> 
        <geometry>
          <cylinder>
            <radius>0.005</radius>
            <length>0.075</length>
          </cylinder>
        </geometry>
        <material>
          <script>
            <name>Gazebo/FlatBlack</name>
            <uri>file://media/materials/scripts/gazebo.material</uri>
          </script>
        </material>
      </visual>
      <visual name='front_right_leg_visual_1'>
        <pose>0.176776695 -0.176776695 -0.05 0 0 0</pose>   <!-- 0.123 -0.22 -0.11 0 0 0 -->
        <geometry>
          <cylinder>
            <radius>0.005</radius>
            <length>0.075</length>
          </cylinder>
        </geometry>
        <material>
          <script>
            <name>Gazebo/FlatBlack</name>
            <uri>file://media/materials/scripts/gazebo.material</uri>
          </script>
        </material>
      </visual>
      <visual name='rear_left_leg_visual_1'>
        <pose>-0.176776695 0.176776695 -0.05 0 0 0</pose>      <!-- -0.140 0.21 -0.11 0 0 0 -->
        <geometry>
          <cylinder>
            <radius>0.005</radius>
            <length>0.075</length>
          </cylinder>
        </geometry>
        <material>
          <script>
            <name>Gazebo/FlatBlack</name>
            <uri>file://media/materials/scripts/gazebo.material</uri>
          </script>
        </material>
      </visual>
      <visual name='rear_right_leg_visual_1'>
        <pose>-0.176776695 -0.176776695 -0.05 0 0 0</pose>    <!-- -0.140 -0.21 -0.11 0 0 0 -->
        <geometry>
          <cylinder>
            <radius>0.005</radius>
            <length>0.075</length>
          </cylinder>
        </geometry>
        <material>
          <script>
            <name>Gazebo/FlatBlack</name>
            <uri>file://media/materials/scripts/gazebo.material</uri>
          </script>
        </material>
      </visual>
    </link>

    <!-- link name='iris/ground_truth/odometry_sensorgt_link'>
      <pose>0 0 0 0 -0 0</pose>
      <inertial>
        <pose>0 0 0 0 -0 0</pose>
        <mass>0.15</mass> 
        <inertia>
          <ixx>0.0001</ixx>   
          <ixy>0</ixy>
          <ixz>0</ixz>
          <iyy>0.0002</iyy>   
          <iyz>0</iyz>
          <izz>0.0002</izz>  
        </inertia>
      </inertial>
    </link>
    <joint name='iris/ground_truth/odometry_sensorgt_joint' type='revolute'>
      <child>iris/ground_truth/odometry_sensorgt_link</child>
      <parent>base_link</parent>
      <axis>
        <xyz>0 0 1</xyz>
        <limit>
          <lower>0</lower>
          <upper>0</upper>
          <effort>0</effort>
          <velocity>0</velocity>
        </limit>
        <dynamics>
          <damping>1.0</damping>
        </dynamics>
        <use_parent_model_frame>1</use_parent_model_frame>
      </axis>
      <physics>
        <ode>
          <implicit_spring_damper>1</implicit_spring_damper>
        </ode>
      </physics>
    </joint-->

    <!-- link name='iris/imu_link'>
      <inertial>
        <pose>0 0 0 0 0 0</pose>
        <mass>0.15</mass>   
        <inertia>
          <ixx>0.00001</ixx>  
          <ixy>0</ixy>
          <ixz>0</ixz>
          <iyy>0.00002</iyy>   
          <iyz>0</iyz>
          <izz>0.00002</izz>   
        </inertia>
      </inertial>
      <sensor name="imu_sensor" type="imu">
        <pose>0 0 0 3.141593 0 0</pose>
        <always_on>1</always_on>
        <update_rate>1000.0</update_rate>
      </sensor>
    </link>
    <joint name='iris/imu_joint' type='revolute'>
      <child>iris/imu_link</child>
      <parent>base_link</parent>
      <axis>
        <xyz>0 0 1</xyz>
        <limit>
          <lower>0</lower>
          <upper>0</upper>
          <effort>0</effort>
          <velocity>0</velocity>
        </limit>
        <dynamics>
          <damping>1.0</damping>
        </dynamics>
        <use_parent_model_frame>1</use_parent_model_frame>
      </axis>
      <physics>
        <ode>
          <implicit_spring_damper>1</implicit_spring_damper>
        </ode>
      </physics>
    </joint-->

<!--
    <link name='iris/imugt_link'>
      <pose>0 0 0 0 -0 0</pose>
      <inertial>
        <pose>0 0 0 0 -0 0</pose>
        <mass>1e-02</mass>
        <inertia>
          <ixx>0.0002</ixx>
          <ixy>0</ixy>
          <ixz>0</ixz>
          <iyy>0.0002</iyy>
          <iyz>0</iyz>
          <izz>0.0002</izz>
        </inertia>
      </inertial>
    </link>
    <joint name='iris/imugt_joint' type='revolute'>
      <child>iris/imugt_link</child>
      <parent>base_link</parent>
      <axis>
        <xyz>0 0 1</xyz>
        <limit>
          <lower>0</lower>
          <upper>0</upper>
          <effort>0</effort>
          <velocity>0</velocity>
        </limit>
        <dynamics>
          <spring_reference>0</spring_reference>
          <spring_stiffness>0</spring_stiffness>
        </dynamics>
        <use_parent_model_frame>1</use_parent_model_frame>
      </axis>
    </joint>
-->

    <link name='rotor_0'>
      <pose>0.181776695 -0.176776695 0.023 0 -0 0</pose>   <!-- 0.13 -0.22 0.023 0 -0 0 -->
      <inertial>
        <pose>0 0 0 0 -0 0</pose>
        <mass>0.025</mass>   <!-- 0.025-->
        <inertia>
          <ixx>9.75e-06</ixx>    <!-- 9.75e-06 -->
          <ixy>0</ixy>
          <ixz>0</ixz>
          <iyy>0.000166704</iyy>   <!-- 0.000166704 -->
          <iyz>0</iyz>
          <izz>0.000167604</izz>   <!-- 0.000167604 -->
        </inertia>
      </inertial>
      <collision name='rotor_0_collision'>
        <pose>0 0 0 0 -0 0</pose>
        <geometry>
          <cylinder>
            <length>0.008</length>
            <radius>0.12</radius>
          </cylinder>
        </geometry>
        <surface>
          <contact>
            <ode/>
          </contact>
          <friction>
            <ode/>
          </friction>
        </surface>
      </collision>
      <visual name='rotor_0_visual'>
        <pose>0 0 0 0 -0 0</pose>
        <geometry>
          <mesh>
            <scale>0.93 0.93 0.93</scale>   <!-- 1 1 1-->
            <uri>model://my_drone/meshes/iris_prop_ccw.dae</uri>
          </mesh>
        </geometry>
        <material>
          <script>
            <name>Gazebo/Blue</name>
            <uri>__default__</uri>
          </script>
        </material>
      </visual>
      <gravity>1</gravity>
      <velocity_decay/>
      <self_collide>0</self_collide>
    </link>
    <joint name='rotor_0_joint' type='revolute'>
      <child>rotor_0</child>
      <parent>base_link</parent>
      <axis>
        <xyz>0 0 1</xyz>
        <limit>
          <lower>-1e+16</lower>
          <upper>1e+16</upper>
        </limit>
        <dynamics>
          <damping>0.004</damping>
        </dynamics>
        <use_parent_model_frame>1</use_parent_model_frame>
      </axis>
      <physics>
        <ode>
          <implicit_spring_damper>1</implicit_spring_damper>
        </ode>
      </physics>
    </joint>
    <link name='rotor_1'>
      <pose>-0.171776695 0.176776695 0.023 0 -0 0</pose>    <!-- -0.13 0.2 0.023 0 -0 0 -->
      <inertial>
        <pose>0 0 0 0 -0 0</pose>
        <mass>0.025</mass>   <!-- 0.025-->
        <inertia>
          <ixx>9.75e-06</ixx>    <!-- 9.75e-06 -->
          <ixy>0</ixy>
          <ixz>0</ixz>
          <iyy>0.000166704</iyy>   <!-- 0.000166704 -->
          <iyz>0</iyz>
          <izz>0.000167604</izz>   <!-- 0.000167604 -->
        </inertia>
      </inertial>
      <collision name='rotor_1_collision'>
        <pose>0 0 0 0 -0 0</pose>
        <geometry>
          <cylinder>
            <length>0.008</length>
            <radius>0.12</radius>
          </cylinder>
        </geometry>
        <surface>
          <contact>
            <ode/>
          </contact>
          <friction>
            <ode/>
          </friction>
        </surface>
      </collision>
      <visual name='rotor_1_visual'>
        <pose>0 0 0 0 -0 0</pose>
        <geometry>
          <mesh>
            <scale>0.93 0.93 0.93</scale>   <!-- 1 1 1-->
            <uri>model://my_drone/meshes/iris_prop_ccw.dae</uri>
          </mesh>
        </geometry>
        <material>
          <script>
            <name>Gazebo/DarkGrey</name>
            <uri>__default__</uri>
          </script>
        </material>
      </visual>
      <gravity>1</gravity>
      <velocity_decay/>
      <self_collide>0</self_collide>
    </link>
    <joint name='rotor_1_joint' type='revolute'>
      <child>rotor_1</child>
      <parent>base_link</parent>
      <axis>
        <xyz>0 0 1</xyz>
        <limit>
          <lower>-1e+16</lower>
          <upper>1e+16</upper>
        </limit>
        <dynamics>
          <damping>0.004</damping>
        </dynamics>
        <use_parent_model_frame>1</use_parent_model_frame>
      </axis>
      <physics>
        <ode>
          <implicit_spring_damper>1</implicit_spring_damper>
        </ode>
      </physics>
    </joint>
    <link name='rotor_2'>
      <pose>0.176776695 0.176776695 0.023 0 -0 0</pose>   <!-- 0.13 0.22 0.023 0 -0 0 -->
      <inertial>
        <pose>0 0 0 0 -0 0</pose>
        <mass>0.025</mass>   <!-- 0.025-->
        <inertia>
          <ixx>9.75e-06</ixx>    <!-- 9.75e-06 -->
          <ixy>0</ixy>
          <ixz>0</ixz>
          <iyy>0.000166704</iyy>   <!-- 0.000166704 -->
          <iyz>0</iyz>
          <izz>0.000167604</izz>   <!-- 0.000167604 -->
        </inertia>
      </inertial>
      <collision name='rotor_2_collision'>
        <pose>0 0 0 0 -0 0</pose>
        <geometry>
          <cylinder>
            <length>0.008</length>  
            <radius>0.12</radius> 
          </cylinder>
        </geometry>
        <surface>
          <contact>
            <ode/>
          </contact>
          <friction>
            <ode/>
          </friction>
        </surface>
      </collision>
      <visual name='rotor_2_visual'>
        <pose>0 0 0 0 -0 0</pose>
        <geometry>
          <mesh>
            <scale>0.93 0.93 0.93</scale>   <!-- 1 1 1-->
            <uri>model://my_drone/meshes/iris_prop_cw.dae</uri>
          </mesh>
        </geometry>
        <material>
          <script>
            <name>Gazebo/Blue</name>
            <uri>__default__</uri>
          </script>
        </material>
      </visual>
      <gravity>1</gravity>
      <velocity_decay/>
      <self_collide>0</self_collide>
    </link>
    <joint name='rotor_2_joint' type='revolute'>
      <child>rotor_2</child>
      <parent>base_link</parent>
      <axis>
        <xyz>0 0 1</xyz>
        <limit>
          <lower>-1e+16</lower>
          <upper>1e+16</upper>
        </limit>
        <dynamics>
          <damping>0.004</damping>
        </dynamics>
        <use_parent_model_frame>1</use_parent_model_frame>
      </axis>
      <physics>
        <ode>
          <implicit_spring_damper>1</implicit_spring_damper>
        </ode>
      </physics>
    </joint>
    <link name='rotor_3'>
      <pose>-0.176776695 -0.176776695 0.023 0 -0 0</pose>     <!-- -0.13 -0.2 0.023 0 -0 0 -->
      <inertial>
        <pose>0 0 0 0 -0 0</pose>
        <mass>0.025</mass>   <!-- 0.025-->
        <inertia>
          <ixx>9.75e-06</ixx>    <!-- 9.75e-06 -->
          <ixy>0</ixy>
          <ixz>0</ixz>
          <iyy>0.000166704</iyy>   <!-- 0.000166704 -->
          <iyz>0</iyz>
          <izz>0.000167604</izz>   <!-- 0.000167604 -->
        </inertia>
      </inertial>
      <collision name='rotor_3_collision'>
        <pose>0 0 0 0 -0 0</pose>
        <geometry>
          <cylinder>
            <length>0.008</length>
            <radius>0.12</radius>
          </cylinder>
        </geometry>
        <surface>
          <contact>
            <ode/>
          </contact>
          <friction>
            <ode/>
          </friction>
        </surface>
      </collision>
      <visual name='rotor_3_visual'>
        <pose>0 0 0 0 -0 0</pose>
        <geometry>
          <mesh>
            <scale>0.93 0.93 0.93</scale>  <!-- 1 1 1-->
            <uri>model://my_drone/meshes/iris_prop_cw.dae</uri>
          </mesh>
        </geometry>
        <material>
          <script>
            <name>Gazebo/DarkGrey</name>
            <uri>__default__</uri>
          </script>
        </material>
      </visual>
      <gravity>1</gravity>
      <velocity_decay/>
      <self_collide>0</self_collide>
    </link>
    <joint name='rotor_3_joint' type='revolute'>
      <child>rotor_3</child>
      <parent>base_link</parent>
      <axis>
        <xyz>0 0 1</xyz>
        <limit>
          <lower>-1e+16</lower>
          <upper>1e+16</upper>
        </limit>
        <dynamics>
          <damping>0.004</damping>
        </dynamics>
        <use_parent_model_frame>1</use_parent_model_frame>
      </axis>
      <physics>
        <ode>
          <implicit_spring_damper>1</implicit_spring_damper>
        </ode>
      </physics>
    </joint>
    <static>0</static>
  </model>
</sdf>
